    <!-- ===========================================================================

Este modelo esta basado en el modelo del robot UR5 de la universidad de leeds
del departamento de robotica del mismo


Autor:  Alexis Alejandro Fraudita Macia


Modelo Original se puede encontrar en: https://github.com/roboticsleeds/mujoco-ur5-model
Descargado el 11 de enero del 2022
Autor:Rafael Papallas
Contacto: @rpapallas (twitter)


Modelo del Robot: UR5 Arm de la empresa Universal-robots Inc

Simulador Mujoco ::Advanced physics simulation engine
          Version : 2.10

===========================================================================-->
<mujoco model="UR5(v1)">

    <!-- configuracion del compilador -->
    <compiler inertiafromgeom='true' angle='radian' meshdir="meshes/V2"/>
    <option  timestep="0.002" gravity="0 0 0"/>

    <!-- valores por defecto para la simulación -->
    <default>
        <light castshadow="false" diffuse="1 1 1"/>
        <joint frictionloss="1" damping="1"/>
    </default>

    <!-- meshes, materiales y texturas -->
    <asset>
        <include file="assets.xml"/>
    </asset>

    <!-- objetos a renderizar -->
    <worldbody>

        <camera name="view2" pos="1.0 0.7 0.3" xyaxes="-1 1 0 0 0 1" fovy="45" ipd="0.068"/>

        <!-- piso -->
        <geom
            name="floor"
            pos="0 0 0"
            size="0 0 .25"
            type="plane"
            material="matplane"
            condim="3"
        />

        <!-- base del robot -->
        <body name="base" pos="0 0 .2">
            <geom size ="1 1 .2" type="box" material="matgeom" rgba="0 0.5 0.5 1"/>
        </body>

        <!-- luces -->
        <light directional="true" pos="-0.5 0.5 3" dir="0 0 -1" />
        <light directional="false" pos="-0.5 0.5 1.5" dir="0 -1 0" />

        <!-- modelo del robot-->
        <body name="robot" pos="0.5 0 0.4">
            <geom
                pos="0 0 0"
                type="mesh"
                rgba="0.7 0.7 0.7 1"
                quat="0.681998 0 0 -0.731354"
                mesh="ur5_base"
            />
    		<body name="base_link" pos="0 0 0.086" quat="-0.03489996 0. 0. -0.99939078">
                <inertial pos="0 0 0" mass="3.7" diaginertia="0.0102675 0.0102675 0.00666" />
                <geom type="mesh" rgba="0.7 0.7 0.7 1" mesh="shoulder" />
                <!-- indicador de actuador 1 -->
                <geom
                    name="base_cap"
                    type="cylinder"
                    pos="0 0 0.05"
                    size="0.06 0.02"
                    rgba="0.596 0.96 1 1"
                    material="RobMat"
                    contype="0"
                    conaffinity="0"
                />
                <joint name="joint1" pos="0 0 0" axis="0 0 1" />


                <body name="shoulder_link" pos="0 0.13585 0" quat="0.73727628 0. -0.67559182 0.">
                    <inertial pos="0 0 0.28" mass="8.393" diaginertia="0.226891 0.226891 0.0151074"/>
                    <geom type="mesh" rgba="0.7 0.7 0.7 1" mesh="upperarm"/>
                    <!-- indicador de actuador 2 -->
                    <geom
                        name="shoulder_cap"
                        type="cylinder"
                        pos="0 0.05 0"
                        quat="0.707107 0.707107 0 0"
                        size="0.06 0.02"
                        rgba="0.596 0.96 1 1"
                        material="RobMat"
                        contype="0"
                        conaffinity="0"
                    />
                    <joint name="joint2" pos="0 0 0" axis="0 1 0" />


                    <body name="elbow_link" pos="0 -0.1197 0.425" quat="0.99904822 0. -0.04361939 0. ">
                        <inertial pos="0 0 0.25" mass="2.275" diaginertia="0.0494433 0.0494433 0.004095" />
                        <geom type="mesh" rgba="0.7 0.7 0.7 1" mesh="forearm" />
                        <!-- indicador de actuador 3 -->
                        <geom
                            name="elbow_cap"
                            type="cylinder"
                            pos="0 0.18 0"
                            quat="0.707107 0.707107 0 0"
                            size="0.06 0.02"
                            rgba="0.596 0.96 1 1"
                            material="RobMat"
                            contype="0"
                            conaffinity="0"
                        />
                        <joint name="joint3" pos="0 0 0" axis="0 1 0"/>

                        <body name="wrist_1_link" pos="0 0 0.39225" quat="0.707107 0. -0.707107 0.">
                            <inertial pos="0 0 0" quat="0.5 0.5 -0.5 0.5" mass="1.219" diaginertia="0.21942 0.111173 0.111173"/>
                            <geom type="mesh" rgba="0.7 0.7 0.7 1" mesh="wrist1"/>
                            <!-- indicador de actuador 4 -->
                            <geom
                                name="wrist_1_cap"
                                type="cylinder"
                                pos="0 -0.05 0"
                                quat="0.707107 0.707107 0 0"
                                size="0.04 0.02"
                                rgba="0.596 0.96 1 1"
                                material="RobMat"
                                contype="0"
                                conaffinity="0"
                            />
                            <joint name="joint4" pos="0 0 0" axis="0 1 0"/>

                            <body name="wrist_2_link" pos="0 0.093 0" quat="0.70710678 0. 0. -0.70710678">
                                <inertial pos="0 0 0" quat="0.5 0.5 -0.5 0.5" mass="1.219" diaginertia="0.21942 0.111173 0.111173"/>
                                <geom type="mesh" rgba="0.7 0.7 0.7 1" friction="0.4 0.4 0.4" mesh="wrist2"/>
                                <!-- indicador de actuador 5 -->
                                <geom
                                    name="wrist_2_cap"
                                    type="cylinder"
                                    pos="0 0 -0.03"
                                    quat="0.70710678 0. 0. -0.70710678"
                                    size="0.04 0.02"
                                    rgba="0.596 0.96 1 1"
                                    material="RobMat"
                                    contype="0"
                                    conaffinity="0"
                                />
                                <joint name="joint5" pos="0 0 0" axis="0 0 1"/>

                                <body name="wrist_3_link" pos="0 0 0.09465" quat="0 0 -1 0">
                                    <inertial pos="0 0 0" quat="0.5 0.5 -0.5 0.5"  mass="0.1879" diaginertia="0.033822 0.0171365 0.0171365"/>
                                    <geom type="mesh" rgba="0.7 0.7 0.7 1" friction="0.8 0.8 0.8" mesh="wrist3"/>
                                    <!-- indicador de actuador 6 -->
                                    <geom
                                        name="wrist_3_cap"
                                        type="cylinder"
                                        pos="0 -0.05 0"
                                        quat="0 0 0.707107 0.707107"
                                        size="0.04 0.02"
                                        rgba="0.596 0.96 1 1"
                                        material="RobMat"
                                        contype="0"
                                        conaffinity="0"
                                    />
                                    <joint name="joint6" pos="0 0 0" axis="0 1 0"/>

                                    <!-- efector final -->
                                    <include file="efector.xml"/>
                                </body>
                            </body>
                        </body>
                    </body>
                </body>
            </body>
        </body>

        <!-- target -->
        <geom
            name="target"
            pos="0 0.0 1.0"
            size="0.03"
            type="sphere"
            rgba="0.9 0.2 0.2 1"
            contype='0'
            conaffinity="0"
        />

    </worldbody>

    <!-- actuadores -->
    <actuator>
        <!-- <velocity name="joint1_velocity" joint="joint1" ctrlrange="-1 1"/>
        <velocity name="joint2_velocity" joint="joint2" ctrlrange="-1 1"/>
        <velocity name="joint3_velocity" joint="joint3" ctrlrange="-1 1"/>
        <velocity name="joint4_velocity" joint="joint4" ctrlrange="-1 1"/>
        <velocity name="joint5_velocity" joint="joint5" ctrlrange="-1 1"/>
        <velocity name="joint6_velocity" joint="joint6" ctrlrange="-1 1"/> -->

        <!-- <position name="joint1_position" joint="joint1"/>
        <position name="joint2_position" joint="joint2"/>
        <position name="joint3_position" joint="joint3"/>
        <position name="joint4_position" joint="joint4"/>
        <position name="joint5_position" joint="joint5"/>
        <position name="joint6_position" joint="joint6"/> -->

        <motor name="joint1_motor" joint="joint1" ctrllimited="true" gear="100" ctrlrange="-3.141 3.141"/>
        <motor name="joint2_motor" joint="joint2" ctrllimited="true" gear="5" ctrlrange="0 3.141"/>
        <motor name="joint3_motor" joint="joint3" ctrllimited="true" gear="5" ctrlrange="-3.141 3.141"/>
        <motor name="joint4_motor" joint="joint4" ctrllimited="true" gear="2" ctrlrange="-3.141 3.141 "/>
        <motor name="joint5_motor" joint="joint5" ctrllimited="true" gear="2" ctrlrange="-3.141 3.141"/>
        <motor name="joint6_motor" joint="joint6" ctrllimited="true" gear="5" ctrlrange="-3.141 3.141"/>
	</actuator>
</mujoco>
