<!-- ===========================================================================

Este modelo esta basado en el modelo del robot UR5 de la universidad de leeds 
del departamento de robotica del mismo


Autor:  Alexis Alejandro Fraudita Macia


Modelo Original se puede encontrar en: https://github.com/roboticsleeds/mujoco-ur5-model
Descargado el 11 de enero del 2022
Autor:Rafael Papallas 
Contacto: @rpapallas (twitter)


Modelo del Robot: UR5 Arm de la empresa Universal-robots Inc

Simulador Mujoco ::Advanced physics simulation engine
          Version : 2.10

===========================================================================-->
<mujoco model="UR5(v1)">

    <!-- configuracion del compilador --> 
    <compiler inertiafromgeom='true' angle='radian' meshdir="meshes/" />
    

    <option  timestep="0.02" gravity="0 0 0" />

    <size njmax="500" nconmax="100"/>

    <!-- valores por defecto para la simulación -->
    <default>
        <light castshadow="false" diffuse="1 1 1"/>
        <joint frictionloss="1" damping="1"/>
    </default>

    <!-- meshes, materiales o textures -->
    <asset>
        <mesh file="base.stl"/>
        <mesh file="shoulder.stl"/>
        <mesh file="upperarm.stl"/>
        <mesh file="forearm.stl"/>
        <mesh file="wrist1.stl"/>
        <mesh file="wrist2.stl"/>
        <mesh file="wrist3.stl"/>
        <mesh file="kinova_robotiq_coupler.stl"/>
        <mesh file="robotiq_85_base_link.stl"/>
        <mesh file="robotiq_85_finger_link.stl"/>
        <mesh file="robotiq_85_finger_tip_link.stl"/>
        <mesh file="robotiq_85_inner_knuckle_link.stl"/>
        <mesh file="robotiq_85_knuckle_link.stl"/>
        
        <material name="RobMat" specular="0.9" shininess="0.5" reflectance="0" rgba="0.7 0.7 0.7 1" emission="0.1"/>
        <material name="Light" specular="0" shininess="0.6" reflectance="0.9" rgba="0.5 0.5 1 1" emission="0.7" />       
        <material name="GriMat" specular="0.9" shininess="0.5" reflectance="0" rgba="0.1 0.1 0.1 1" emission="0.1" />

        <texture
            type="skybox" builtin="gradient" rgb1="0.3 0.5 0.7"
            rgb2="0 0 0"
            width="512" height="512"
        />

        <texture
            name="texplane" type="2d" builtin="checker" rgb1=".2 .3 .4"
            rgb2=".1 0.15 0.2" width="512" height="512" mark="cross"
            markrgb=".8 .8 .8"
        />

        <texture
            name="texgeom" type="cube" builtin="flat" mark="cross"
            width="127" height="1278" rgb1="0.8 0.6 0.4"
            rgb2="0.8 0.6 0.4" markrgb="1 1 1" random="0.01"
        />

        <material
            name="matplane" texture="texplane"
            texrepeat="1 1" texuniform="true"
        />

        <material
            name="matgeom" texture="texgeom" texuniform="true"
            rgba="0.8 0.6 .4 1"
        />
    </asset>

    <!-- objetos a renderizar -->
    <worldbody>

        <!-- piso -->
        <geom
            name="floor" pos="0 0 0" size="0 0 .25" type="plane"
            material="matplane"
            condim="3"
        />


        <!-- base del robot -->
        <body name="base" pos="0 0 .2">
            <geom
                size ="1 1 .2" type="box"
                material="matgeom" rgba="0 0.5 0.5 1"
            />
        </body>

        <!-- luces -->
        <light directional="true" pos="-0.5 0.5 3" dir="0 0 -1" />
        <light directional="false" pos="-0.5 0.5 1.5" dir="0 -1 0" />

        <!-- modelo del robot-->
        <body name="base_link" pos="0.4 -0.4 0.4" quat="0.3826834324 0 0 0.9238795325" >
            <inertial pos="0 0 0" quat="0.5 0.5 -0.5 0.5" mass="4" diaginertia="0.0072 0.00443333 0.00443333" />
            <geom name="base_mesh" type="mesh" mesh="base" material="RobMat" />
            <geom 
                name="base_cap" type="cylinder" pos="0 0 0.14" size="0.06 0.02" 
                rgba="0.596 0.96 1 1" material="RobMat" contype="0" conaffinity="0" 
            />

            <body name="shoulder_link" pos="0 0 0.089159">
                <inertial pos="0 0 0" mass="3.7" diaginertia="0.0102675 0.0102675 0.00666" />
                <geom name="shoulder_mesh" type="mesh" mesh="shoulder" material="RobMat" />
                <geom 
                    name="shoulder_cap" type="cylinder" pos="0 0.185 0" quat="0.707107 0.707107 0 0" size="0.06 0.02" 
                    rgba="0.596 0.96 1 1" material="RobMat" contype="0" conaffinity="0" 
                />
                <joint name="joint1" pos="0 0 0" axis="0 0 1" />

                <body name="upper_arm_link" pos="0 0.13585 0" quat="0.707107 0 0.707107 0">
                    <inertial pos="0 0 0.28" mass="8.393" diaginertia="0.226891 0.226891 0.0151074" />
                    <geom name="upperarm_mesh" type="mesh" mesh="upperarm" material="RobMat" />
                    <joint name="joint2" pos="0 0 0" axis="0 1 0" />

                    <body name="forearm_link" pos="0 -0.1197 0.425">
                        <inertial pos="0 0 0.25" mass="2.275" diaginertia="0.0494433 0.0494433 0.004095" />
                        <geom name="forearm_mesh" type="mesh" mesh="forearm" material="RobMat" />

                        <!--camera name="forearm_camera" pos="0 0.1 0.07" euler="3.14159265 0 1.570796" /-->

                        <geom 
                            name="forearm_cap" type="cylinder" pos="0 0.17 0" quat="0.707107 0.707107 0 0" size="0.06 0.02" 
                            rgba="0.596 0.96 1 1" material="RobMat" contype="0" conaffinity="0" 
                        />
                        <joint name="joint3" pos="0 0 0" axis="0 1 0" />

                        <body name="wrist1_link" pos="0 0 0.39225" quat="0.707107 0 0.707107 0">
                            <inertial pos="0 0 0" quat="0.5 0.5 -0.5 0.5" mass="1.219" diaginertia="0.21942 0.111173 0.111173" />
                            <geom name="wrist1_mesh" type="mesh" mesh="wrist1" material="RobMat" />
                            <geom 
                                name="wrist1_cap" type="cylinder" pos="0 -0.045 0" quat="0.707107 0.707107 0 0" size="0.04 0.015" 
                                rgba="0.596 0.96 1 1" material="RobMat" contype="0" conaffinity="0" 
                            />
                            <joint name="joint4" pos="0 0 0" axis="0 1 0" />

                            <body name="wrist2_link" pos="0 0.093 0">
                                <inertial pos="0 0 0" quat="0.5 0.5 -0.5 0.5" mass="1.219" diaginertia="0.21942 0.111173 0.111173" />
                                <geom name="wrist2_mesh" type="mesh" mesh="wrist2" material="RobMat" />
                                <geom 
                                    name="wrist2_cap" type="cylinder" pos="0 0 -0.045" quat="0.707107 0 0 0.707107" size="0.04 0.015" 
                                    rgba="0.596 0.96 1 1" material="RobMat" contype="0" conaffinity="0" 
                                />
                                <joint name="joint5" pos="0 0 0" axis="0 0 1" />

                                <body name="wrist3_link" pos="0 0 0.09465" quat="0.707107 0 -0.707107 0" >
                                    <inertial 
                                        pos="0 0 0" quat="0.5 0.5 -0.5 0.5" mass="0.1879" 
                                        diaginertia="0.033822 0.0171365 0.0171365" 
                                    />
                                    <geom name="wrist3_mesh" type="mesh" mesh="wrist3" material="RobMat" contype="1" conaffinity="1" />
                                    <geom 
                                        name="wrist3_cap" type="cylinder" pos="0 -0.045 0" quat="0.707107 0.707107 0 0" 
                                        size="0.04 0.015" rgba="0.596 0.96 1 1" material="RobMat" contype="0" conaffinity="0" 
                                    />
                                    <joint name="joint6" pos="0 0 0" axis="0 1 0" />

                                    <body name="ee_link" pos="0 0.0823 0" quat="0.707107 -0.707107 0 0">
                                        <inertial pos="0 0.0823 0" quat="0.707107 -0.707107 0 0" mass="0" diaginertia="0 0 0" />

                                        <!--camera name="gripper_camera" euler="0 3.14159265 0" fovy="63.5" /-->
                                        <geom name="light_1" type="sphere" size="0.005" pos="0.035 0 0.0166" material="Light" />
                                        <geom name="light_2" type="sphere" size="0.005" pos="-0.035 0 0.0166" material="Light" />
                                        <geom 
                                            name="kinova_robotiq_coupler_mesh" type="mesh" mesh="kinova_robotiq_coupler" 
                                            pos="0 0 0.0466" material="GriMat" 
                                        />
                                        <geom 
                                            name="robotiq_85_base_link_mesh" type="mesh" mesh="robotiq_85_base_link" 
                                            pos="0 0 0.0016" quat="0.707107 0 -0.707107 0" material="GriMat" 
                                        />

                                        <body name="right_driver" pos="0 -0.0306011 0.054904" quat="0.707107 0 -0.707107 0">
                                            <geom 
                                                name="right_driver_mesh" type="mesh" mesh="robotiq_85_knuckle_link" material="GriMat" 
                                                contype="0" conaffinity="0" 
                                            />
                                            <joint name="joint7_1" axis="0 0 1" type="hinge" limited="true" range="0 0.872664626" />

                                        
                                            <body name="right_coupler" pos="0 -0.0315 0">
                                                <geom 
                                                    name="right_coupler_mesh" type="mesh" mesh="robotiq_85_finger_link" 
                                                    material="GriMat" contype="0" conaffinity="0" 
                                                />
                                                <joint name="joint8_1" axis="0 0 1" type="hinge" limited="true" range="0 2.967059728" />

                                                <body name="right_follower_link" pos="0.0475 -0.006 0">
                                                    <geom 
                                                        name="right_follower_mesh" pos="0.0025 0.021 0" 
                                                        type="mesh" mesh="robotiq_85_finger_tip_link" material="GriMat" 
                                                    />
                                                    <joint 
                                                        name="joint9_1" axis="0 0 1" type="hinge" 
                                                        limited="true" range="0 2.967059728" 
                                                    />
                                                </body>

                                            </body>

                                        </body>

                                        <body name="right_spring_link" pos="0.0016 -0.012 0.0614" quat="0.707107 0 -0.707107 0">
                                            <geom 
                                                name="right_spring_mesh" type="mesh" pos="0 -0.0005 0.0016" 
                                                mesh="robotiq_85_inner_knuckle_link" material="GriMat" contype="0" conaffinity="0" 
                                            />
                                            <joint name="joint10_1" axis="0 0 1" type="hinge" limited="true" range="0 1" />
                                        </body>


                                        <body name="left_driver" pos="0 0.0306011 0.054904" quat="0 0.707107 0 0.707107">
                                            <geom 
                                                name="left_driver_mesh" type="mesh" mesh="robotiq_85_knuckle_link" material="GriMat" 
                                                contype="0" conaffinity="0" 
                                            />
                                            <joint name="joint7_2" axis="0 0 1" type="hinge" limited="true" range="0 0.872664626" />

                                        
                                            <body name="left_coupler" pos="0 -0.0315 0">
                                                <geom 
                                                    name="left_coupler_mesh" type="mesh" mesh="robotiq_85_finger_link" 
                                                    material="GriMat" contype="0" conaffinity="0" 
                                                />
                                                <joint name="joint8_2" axis="0 0 1" type="hinge" limited="true" range="0 2.967059728" />

                                                <body name="left_follower_link" pos="0.0475 -0.006 0">
                                                    <geom 
                                                        name="left_follower_mesh" pos="0.0025 0.021 0" type="mesh" 
                                                        mesh="robotiq_85_finger_tip_link" material="GriMat" 
                                                    />
                                                    <joint 
                                                        name="joint9_2" axis="0 0 1" type="hinge" 
                                                        limited="true" range="0 2.967059728" 
                                                    />
                                                </body>

                                            </body>

                                        </body>

                                        <body name="left_spring_link" pos="0.0016 0.012 0.0614" quat="0 0.707107 0 0.707107">
                                            <geom 
                                                name="left_spring_mesh" type="mesh" pos="0 0.0005 0.0016" 
                                                mesh="robotiq_85_inner_knuckle_link" 
                                                material="GriMat" contype="0" conaffinity="0" 
                                            />
                                            <joint name="joint10_2" axis="0 0 1" type="hinge" limited="true" range="0 1" />
                                        </body>

                                    </body>
                                </body>
                            </body>
                        </body>
                    </body>
                </body>
            </body>
        </body>

        <!-- target -->
        <body name="target_body_1" pos="0 0.5 0.6">
            <geom name="target_1" pos="0 0 0" size="0.025 0.025 0.025" type="box" rgba="0.9529411765 0.8 0.03529411765 1" />
        </body>
    </worldbody>
</mujoco>
